model
name = Test Object
revision = 8416
size = 20 40 20
origin = -y
shell = Outline 0.25
material type = toon, lighting = smooth, deform = 1 1
  colors = B:#620042
material type = basic, lighting = smooth, roughness = 0, refractionRatio = 1, side = back
  colors = Outline:#000
voxels
16(380-420B)380-3(335B4(5-15B)385-)335B4(5-15B)5-
