model
name = Test Object
revision = 8413
size = 20 40 20
origin = -y
shell = Outline 0.25
material type = toon, lighting = smooth, deform = 1 1
  colors = B:#620042
material type = basic, lighting = smooth, roughness = 0, refractionRatio = 1, side = back
  colors = Outline:#000
voxels
16(380-420B)380-398B-21B380-2(398B2-18B382-)377B3-17B3-18B2-
